Workbook

Sheet Projections
A1: Today | B1: =TODAY() -> 46044 | V1: 3.03 | X1: ='2026'!BJ1 -> 117 | Y1: ='2026'!BK1 -> -155 | Z1: ='2026'!BL1 -> -126 | AA1: ='2026'!BM1 -> 102
A2: Tomorrow | B2: =TODAY()+1 -> 46045 | H2: Starter | I2: Starter | J2: Backup | K2: Backup | L2: Starter | M2: Starter | N2: Backup | O2: Backup | V2: 3.26 | X2: ='2026'!BJ2 -> -117 | Y2: ='2026'!BK2 -> 155 | Z2: ='2026'!BL2 -> 126 | AA2: ='2026'!BM2 -> -102
A4: Date | B4: Code | C4: Game ID | D4: GF | E4: Adjustment | F4: Team | G4: Team # | H4: Starter | I4: Backup | J4: Starter | K4: Backup | L4: Starter | M4: Backup | N4: Starter | O4: Backup | P4: Confidence Level | Q4: Starter | R4: Backup | S4: Starter % | T4: Wghtd | W4: Team | X4: ML | Y4: 5.5 | Z4: 6 | AA4: 6.5
A5: =IF(D5=0,"0",(_xlfn.XLOOKUP(B5,'2026'!A:A,'2026'!C:C))) -> 46044 | B5: {=_xlfn._xlws.FILTER('2026'!A:B,('2026'!C:C=Projections!B1)+('2026'!C:C=Projections!B2))} -> 2025020795 BUF | C5: 2025020795 | D5: =_xlfn.XLOOKUP(B5,'2026'!A:A,'2026'!AT:AT) -> 2.9477539 | E5: =_xlfn.XLOOKUP(B5,'2026'!A:A,'2026'!Z:Z) -> 0.99 | F5: =_xlfn.XLOOKUP(B5,'2026'!A:A,'2026'!E:E) -> BUF | G5: =D5/E6 -> 2.9477539 | H5: =SUMIFS(Goalies!$J:$J,Goalies!$C:$C,Projections!$F5,Goalies!$A:$A,Projections!H$2) -> 1.015 | I5: =SUMIFS(Goalies!$J:$J,Goalies!$C:$C,Projections!$F5,Goalies!$A:$A,Projections!I$2) -> 1.015 | J5: =SUMIFS(Goalies!$J:$J,Goalies!$C:$C,Projections!$F5,Goalies!$A:$A,Projections!J$2) -> 0.99 | K5: =SUMIFS(Goalies!$J:$J,Goalies!$C:$C,Projections!$F5,Goalies!$A:$A,Projections!K$2) -> 0.99 | L5: =IFERROR($G5*H6,0) -> 2.9477539 | M5: =IFERROR($G5*I6,0) -> 5.9102465 | N5: =IFERROR($G5*J6,0) -> 2.9477539 | O5: =IFERROR($G5*K6,0) -> 5.9102465 | P5: =_xlfn.XLOOKUP(B5,'2026'!A:A,'2026'!AS:AS) -> Neutral | Q5: {=_xlfn.XLOOKUP(1, (Goalies!C:C=Projections!W5)*(Goalies!A:A=Projections!$Q$4), Goalies!D:D)} -> Ukko-Pekka Luukkonen | R5: {=_xlfn.XLOOKUP(1, (Goalies!C:C=Projections!W5)*(Goalies!A:A=Projections!$R$4), Goalies!D:D)} -> Alex Lyon | S5: 1 | T5: =IFERROR(L5*S6+(1-S6)*M5,0) -> 5.9102465 | W5: =F5 -> BUF | X5: ='2026'!BJ3 -> #N/A | Y5: ='2026'!BK3 -> #N/A | Z5: ='2026'!BL3 -> #N/A | AA5: ='2026'!BM3 -> #N/A
A6: =IF(D6=0,"0",(_xlfn.XLOOKUP(B6,'2026'!A:A,'2026'!C:C))) -> 46044 | B6: 2025020795 MTL | C6: 2025020795 | D6: =_xlfn.XLOOKUP(B6,'2026'!A:A,'2026'!AT:AT) -> 3.2268201 | E6: =_xlfn.XLOOKUP(B6,'2026'!A:A,'2026'!Z:Z) -> 1 | F6: =_xlfn.XLOOKUP(B6,'2026'!A:A,'2026'!E:E) -> MTL | G6: =D6/E5 -> 3.2594142 | H6: =SUMIFS(Goalies!$J:$J,Goalies!$C:$C,Projections!$F6,Goalies!$A:$A,Projections!H$4) -> 1 | I6: =SUMIFS(Goalies!$J:$J,Goalies!$C:$C,Projections!$F6,Goalies!$A:$A,Projections!I$4) -> 2.005 | J6: =SUMIFS(Goalies!$J:$J,Goalies!$C:$C,Projections!$F6,Goalies!$A:$A,Projections!J$4) -> 1 | K6: =SUMIFS(Goalies!$J:$J,Goalies!$C:$C,Projections!$F6,Goalies!$A:$A,Projections!K$4) -> 2.005 | L6: =IFERROR($G6*H5,0) -> 3.3083054 | M6: =IFERROR($G6*I5,0) -> 3.3083054 | N6: =IFERROR($G6*J5,0) -> 3.2268201 | O6: =IFERROR($G6*K5,0) -> 3.2268201 | P6: =_xlfn.XLOOKUP(B6,'2026'!A:A,'2026'!AS:AS) -> Neutral | Q6: {=_xlfn.XLOOKUP(1, (Goalies!C:C=Projections!W6)*(Goalies!A:A=Projections!$Q$4), Goalies!D:D)} -> Sam Montembeault | R6: {=_xlfn.XLOOKUP(1, (Goalies!C:C=Projections!W6)*(Goalies!A:A=Projections!$R$4), Goalies!D:D)} -> Jakub Dobes | S6: 0 | T6: =IFERROR(L6*S5+(1-S5)*N6,0) -> 3.3083054 | W6: =F6 -> MTL | X6: ='2026'!BJ4 -> #N/A | Y6: ='2026'!BK4 -> #N/A | Z6: ='2026'!BL4 -> #N/A | AA6: ='2026'!BM4 -> #N/A
A7: =IF(D7=0,"0",(_xlfn.XLOOKUP(B7,'2026'!A:A,'2026'!C:C))) -> 46044 | B7: 2025020796 CHI | C7: 2025020796 | D7: =_xlfn.XLOOKUP(B7,'2026'!A:A,'2026'!AT:AT) -> 2.3702672 | E7: =_xlfn.XLOOKUP(B7,'2026'!A:A,'2026'!Z:Z) -> 0.96 | F7: =_xlfn.XLOOKUP(B7,'2026'!A:A,'2026'!E:E) -> CHI | G7: =D7/E8 -> 2.3702672 | H7: =SUMIFS(Goalies!$J:$J,Goalies!$C:$C,Projections!$F7,Goalies!$A:$A,Projections!H$2) -> 0.96 | I7: =SUMIFS(Goalies!$J:$J,Goalies!$C:$C,Projections!$F7,Goalies!$A:$A,Projections!I$2) -> 0.96 | J7: =SUMIFS(Goalies!$J:$J,Goalies!$C:$C,Projections!$F7,Goalies!$A:$A,Projections!J$2) -> 1.06 | K7: =SUMIFS(Goalies!$J:$J,Goalies!$C:$C,Projections!$F7,Goalies!$A:$A,Projections!K$2) -> 1.06 | L7: =IFERROR($G7*H8,0) -> 2.4769292 | M7: =IFERROR($G7*I8,0) -> 2.3939699 | N7: =IFERROR($G7*J8,0) -> 2.4769292 | O7: =IFERROR($G7*K8,0) -> 2.3939699 | P7: =_xlfn.XLOOKUP(B7,'2026'!A:A,'2026'!AS:AS) -> Weak | Q7: {=_xlfn.XLOOKUP(1, (Goalies!C:C=Projections!W7)*(Goalies!A:A=Projections!$Q$4), Goalies!D:D)} -> Spencer Knight | R7: {=_xlfn.XLOOKUP(1, (Goalies!C:C=Projections!W7)*(Goalies!A:A=Projections!$R$4), Goalies!D:D)} -> Arvid Soderblom | S7: 0 | T7: =IFERROR(L7*S8+(1-S8)*M7,0) -> 2.3939699 | W7: =F7 -> CHI | X7: ='2026'!BJ5 -> 312 | Y7: ='2026'!BK5 -> -191 | Z7: ='2026'!BL5 -> -156 | AA7: ='2026'!BM5 -> -116
A8: =IF(D8=0,"0",(_xlfn.XLOOKUP(B8,'2026'!A:A,'2026'!C:C))) -> 46044 | B8: 2025020796 CAR | C8: 2025020796 | D8: =_xlfn.XLOOKUP(B8,'2026'!A:A,'2026'!AT:AT) -> 3.8355292 | E8: =_xlfn.XLOOKUP(B8,'2026'!A:A,'2026'!Z:Z) -> 1 | F8: =_xlfn.XLOOKUP(B8,'2026'!A:A,'2026'!E:E) -> CAR | G8: =D8/E7 -> 3.9953429 | H8: =SUMIFS(Goalies!$J:$J,Goalies!$C:$C,Projections!$F8,Goalies!$A:$A,Projections!H$4) -> 1.045 | I8: =SUMIFS(Goalies!$J:$J,Goalies!$C:$C,Projections!$F8,Goalies!$A:$A,Projections!I$4) -> 1.01 | J8: =SUMIFS(Goalies!$J:$J,Goalies!$C:$C,Projections!$F8,Goalies!$A:$A,Projections!J$4) -> 1.045 | K8: =SUMIFS(Goalies!$J:$J,Goalies!$C:$C,Projections!$F8,Goalies!$A:$A,Projections!K$4) -> 1.01 | L8: =IFERROR($G8*H7,0) -> 3.8355292 | M8: =IFERROR($G8*I7,0) -> 3.8355292 | N8: =IFERROR($G8*J7,0) -> 4.2350635 | O8: =IFERROR($G8*K7,0) -> 4.2350635 | P8: =_xlfn.XLOOKUP(B8,'2026'!A:A,'2026'!AS:AS) -> Weak | Q8: {=_xlfn.XLOOKUP(1, (Goalies!C:C=Projections!W8)*(Goalies!A:A=Projections!$Q$4), Goalies!D:D)} -> Frederik Andersen | R8: {=_xlfn.XLOOKUP(1, (Goalies!C:C=Projections!W8)*(Goalies!A:A=Projections!$R$4), Goalies!D:D)} -> Pyotr Kochetkov | S8: 0 | T8: =IFERROR(L8*S7+(1-S7)*N8,0) -> 4.2350635 | W8: =F8 -> CAR | X8: ='2026'!BJ6 -> -312 | Y8: ='2026'!BK6 -> 191 | Z8: ='2026'!BL6 -> 156 | AA8: ='2026'!BM6 -> 116
A9: =IF(D9=0,"0",(_xlfn.XLOOKUP(B9,'2026'!A:A,'2026'!C:C))) -> 46044 | B9: 2025020797 DAL | C9: 2025020797 | D9: =_xlfn.XLOOKUP(B9,'2026'!A:A,'2026'!AT:AT) -> 3.0151744 | E9: =_xlfn.XLOOKUP(B9,'2026'!A:A,'2026'!Z:Z) -> 1.005 | F9: =_xlfn.XLOOKUP(B9,'2026'!A:A,'2026'!E:E) -> DAL | G9: =D9/E10 -> 3.0924866 | H9: =SUMIFS(Goalies!$J:$J,Goalies!$C:$C,Projections!$F9,Goalies!$A:$A,Projections!H$2) -> 0.995 | I9: =SUMIFS(Goalies!$J:$J,Goalies!$C:$C,Projections!$F9,Goalies!$A:$A,Projections!I$2) -> 0.995 | J9: =SUMIFS(Goalies!$J:$J,Goalies!$C:$C,Projections!$F9,Goalies!$A:$A,Projections!J$2) -> 1.005 | K9: =SUMIFS(Goalies!$J:$J,Goalies!$C:$C,Projections!$F9,Goalies!$A:$A,Projections!K$2) -> 1.005 | L9: =IFERROR($G9*H10,0) -> 3.0151744 | M9: =IFERROR($G9*I10,0) -> 3.2471109 | N9: =IFERROR($G9*J10,0) -> 3.0151744 | O9: =IFERROR($G9*K10,0) -> 3.2471109 | P9: =_xlfn.XLOOKUP(B9,'2026'!A:A,'2026'!AS:AS) -> Neutral | Q9: {=_xlfn.XLOOKUP(1, (Goalies!C:C=Projections!W9)*(Goalies!A:A=Projections!$Q$4), Goalies!D:D)} -> Jake Oettinger | R9: {=_xlfn.XLOOKUP(1, (Goalies!C:C=Projections!W9)*(Goalies!A:A=Projections!$R$4), Goalies!D:D)} -> Casey DeSmith | S9: 0 | T9: =IFERROR(L9*S10+(1-S10)*M9,0) -> 3.0151744 | W9: =F9 -> DAL | X9: ='2026'!BJ7 -> 104 | Y9: ='2026'!BK7 -> -134 | Z9: ='2026'!BL7 -> -107 | AA9: ='2026'!BM7 -> 118
A10: =IF(D10=0,"0",(_xlfn.XLOOKUP(B10,'2026'!A:A,'2026'!C:C))) -> 46044 | B10: 2025020797 CBJ | C10: 2025020797 | D10: =_xlfn.XLOOKUP(B10,'2026'!A:A,'2026'!AT:AT) -> 3.0555627 | E10: =_xlfn.XLOOKUP(B10,'2026'!A:A,'2026'!Z:Z) -> 0.975 | F10: =_xlfn.XLOOKUP(B10,'2026'!A:A,'2026'!E:E) -> CBJ | G10: =D10/E9 -> 3.0403609 | H10: =SUMIFS(Goalies!$J:$J,Goalies!$C:$C,Projections!$F10,Goalies!$A:$A,Projections!H$4) -> 0.975 | I10: =SUMIFS(Goalies!$J:$J,Goalies!$C:$C,Projections!$F10,Goalies!$A:$A,Projections!I$4) -> 1.05 | J10: =SUMIFS(Goalies!$J:$J,Goalies!$C:$C,Projections!$F10,Goalies!$A:$A,Projections!J$4) -> 0.975 | K10: =SUMIFS(Goalies!$J:$J,Goalies!$C:$C,Projections!$F10,Goalies!$A:$A,Projections!K$4) -> 1.05 | L10: =IFERROR($G10*H9,0) -> 3.0251591 | M10: =IFERROR($G10*I9,0) -> 3.0251591 | N10: =IFERROR($G10*J9,0) -> 3.0555627 | O10: =IFERROR($G10*K9,0) -> 3.0555627 | P10: =_xlfn.XLOOKUP(B10,'2026'!A:A,'2026'!AS:AS) -> Neutral | Q10: {=_xlfn.XLOOKUP(1, (Goalies!C:C=Projections!W10)*(Goalies!A:A=Projections!$Q$4), Goalies!D:D)} -> Jet Greaves | R10: {=_xlfn.XLOOKUP(1, (Goalies!C:C=Projections!W10)*(Goalies!A:A=Projections!$R$4), Goalies!D:D)} -> Elvis Merzlikins | S10: 1 | T10: =IFERROR(L10*S9+(1-S9)*N10,0) -> 3.0555627 | W10: =F10 -> CBJ | X10: ='2026'!BJ8 -> -104 | Y10: ='2026'!BK8 -> 134 | Z10: ='2026'!BL8 -> 107 | AA10: ='2026'!BM8 -> -118
A11: =IF(D11=0,"0",(_xlfn.XLOOKUP(B11,'2026'!A:A,'2026'!C:C))) -> 46044 | B11: 2025020794 VGK | C11: 2025020794 | D11: =_xlfn.XLOOKUP(B11,'2026'!A:A,'2026'!AT:AT) -> 3.2514257 | E11: =_xlfn.XLOOKUP(B11,'2026'!A:A,'2026'!Z:Z) -> 0.99 | F11: =_xlfn.XLOOKUP(B11,'2026'!A:A,'2026'!E:E) -> VGK | G11: =D11/E12 -> 3.1263709 | H11: =SUMIFS(Goalies!$J:$J,Goalies!$C:$C,Projections!$F11,Goalies!$A:$A,Projections!H$2) -> 1 | I11: =SUMIFS(Goalies!$J:$J,Goalies!$C:$C,Projections!$F11,Goalies!$A:$A,Projections!I$2) -> 1 | J11: =SUMIFS(Goalies!$J:$J,Goalies!$C:$C,Projections!$F11,Goalies!$A:$A,Projections!J$2) -> 2.04 | K11: =SUMIFS(Goalies!$J:$J,Goalies!$C:$C,Projections!$F11,Goalies!$A:$A,Projections!K$2) -> 2.04 | L11: =IFERROR($G11*H12,0) -> 3.0482116 | M11: =IFERROR($G11*I12,0) -> 3.2514257 | N11: =IFERROR($G11*J12,0) -> 3.0482116 | O11: =IFERROR($G11*K12,0) -> 3.2514257 | P11: =_xlfn.XLOOKUP(B11,'2026'!A:A,'2026'!AS:AS) -> Weak | Q11: {=_xlfn.XLOOKUP(1, (Goalies!C:C=Projections!W11)*(Goalies!A:A=Projections!$Q$4), Goalies!D:D)} -> Adin Hill | R11: {=_xlfn.XLOOKUP(1, (Goalies!C:C=Projections!W11)*(Goalies!A:A=Projections!$R$4), Goalies!D:D)} -> Akira Schmid | S11: 0 | T11: =IFERROR(L11*S12+(1-S12)*M11,0) -> 3.2514257 | W11: =F11 -> VGK | X11: ='2026'!BJ9 -> #N/A | Y11: ='2026'!BK9 -> #N/A | Z11: ='2026'!BL9 -> #N/A | AA11: ='2026'!BM9 -> #N/A
A12: =IF(D12=0,"0",(_xlfn.XLOOKUP(B12,'2026'!A:A,'2026'!C:C))) -> 46044 | B12: 2025020794 BOS | C12: 2025020794 | D12: =_xlfn.XLOOKUP(B12,'2026'!A:A,'2026'!AT:AT) -> 2.863222 | E12: =_xlfn.XLOOKUP(B12,'2026'!A:A,'2026'!Z:Z) -> 1.04 | F12: =_xlfn.XLOOKUP(B12,'2026'!A:A,'2026'!E:E) -> BOS | G12: =D12/E11 -> 2.8921434 | H12: =SUMIFS(Goalies!$J:$J,Goalies!$C:$C,Projections!$F12,Goalies!$A:$A,Projections!H$4) -> 0.975 | I12: =SUMIFS(Goalies!$J:$J,Goalies!$C:$C,Projections!$F12,Goalies!$A:$A,Projections!I$4) -> 1.04 | J12: =SUMIFS(Goalies!$J:$J,Goalies!$C:$C,Projections!$F12,Goalies!$A:$A,Projections!J$4) -> 0.975 | K12: =SUMIFS(Goalies!$J:$J,Goalies!$C:$C,Projections!$F12,Goalies!$A:$A,Projections!K$4) -> 1.04 | L12: =IFERROR($G12*H11,0) -> 2.8921434 | M12: =IFERROR($G12*I11,0) -> 2.8921434 | N12: =IFERROR($G12*J11,0) -> 5.8999725 | O12: =IFERROR($G12*K11,0) -> 5.8999725 | P12: =_xlfn.XLOOKUP(B12,'2026'!A:A,'2026'!AS:AS) -> Weak | Q12: {=_xlfn.XLOOKUP(1, (Goalies!C:C=Projections!W12)*(Goalies!A:A=Projections!$Q$4), Goalies!D:D)} -> Jeremy Swayman | R12: {=_xlfn.XLOOKUP(1, (Goalies!C:C=Projections!W12)*(Goalies!A:A=Projections!$R$4), Goalies!D:D)} -> Joonas Korpisalo | S12: 0 | T12: =IFERROR(L12*S11+(1-S11)*N12,0) -> 5.8999725 | W12: =F12 -> BOS | X12: ='2026'!BJ10 -> #N/A | Y12: ='2026'!BK10 -> #N/A | Z12: ='2026'!BL10 -> #N/A | AA12: ='2026'!BM10 -> #N/A
A13: =IF(D13=0,"0",(_xlfn.XLOOKUP(B13,'2026'!A:A,'2026'!C:C))) -> 46044 | B13: 2025020799 FLA | C13: 2025020799 | D13: =_xlfn.XLOOKUP(B13,'2026'!A:A,'2026'!AT:AT) -> 2.933464 | E13: =_xlfn.XLOOKUP(B13,'2026'!A:A,'2026'!Z:Z) -> 1.005 | F13: =_xlfn.XLOOKUP(B13,'2026'!A:A,'2026'!E:E) -> FLA | G13: =D13/E14 -> 3.0398591 | H13: =SUMIFS(Goalies!$J:$J,Goalies!$C:$C,Projections!$F13,Goalies!$A:$A,Projections!H$2) -> 0.995 | I13: =SUMIFS(Goalies!$J:$J,Goalies!$C:$C,Projections!$F13,Goalies!$A:$A,Projections!I$2) -> 0.995 | J13: =SUMIFS(Goalies!$J:$J,Goalies!$C:$C,Projections!$F13,Goalies!$A:$A,Projections!J$2) -> 1.005 | K13: =SUMIFS(Goalies!$J:$J,Goalies!$C:$C,Projections!$F13,Goalies!$A:$A,Projections!K$2) -> 1.005 | L13: =IFERROR($G13*H14,0) -> 2.933464 | M13: =IFERROR($G13*I14,0) -> 3.2222506 | N13: =IFERROR($G13*J14,0) -> 2.933464 | O13: =IFERROR($G13*K14,0) -> 3.2222506 | P13: =_xlfn.XLOOKUP(B13,'2026'!A:A,'2026'!AS:AS) -> Weak | Q13: {=_xlfn.XLOOKUP(1, (Goalies!C:C=Projections!W13)*(Goalies!A:A=Projections!$Q$4), Goalies!D:D)} -> Sergei Bobrovsky | R13: {=_xlfn.XLOOKUP(1, (Goalies!C:C=Projections!W13)*(Goalies!A:A=Projections!$R$4), Goalies!D:D)} -> Daniil Tarasov | S13: 1 | T13: =IFERROR(L13*S14+(1-S14)*M13,0) -> 2.933464 | W13: =F13 -> FLA | X13: ='2026'!BJ11 -> -104 | Y13: ='2026'!BK11 -> -117 | Z13: ='2026'!BL11 -> 109 | AA13: ='2026'!BM11 -> 135
A14: =IF(D14=0,"0",(_xlfn.XLOOKUP(B14,'2026'!A:A,'2026'!C:C))) -> 46044 | B14: 2025020799 WPG | C14: 2025020799 | D14: =_xlfn.XLOOKUP(B14,'2026'!A:A,'2026'!AT:AT) -> 2.9495483 | E14: =_xlfn.XLOOKUP(B14,'2026'!A:A,'2026'!Z:Z) -> 0.965 | F14: =_xlfn.XLOOKUP(B14,'2026'!A:A,'2026'!E:E) -> WPG | G14: =D14/E13 -> 2.934874 | H14: =SUMIFS(Goalies!$J:$J,Goalies!$C:$C,Projections!$F14,Goalies!$A:$A,Projections!H$4) -> 0.965 | I14: =SUMIFS(Goalies!$J:$J,Goalies!$C:$C,Projections!$F14,Goalies!$A:$A,Projections!I$4) -> 1.06 | J14: =SUMIFS(Goalies!$J:$J,Goalies!$C:$C,Projections!$F14,Goalies!$A:$A,Projections!J$4) -> 0.965 | K14: =SUMIFS(Goalies!$J:$J,Goalies!$C:$C,Projections!$F14,Goalies!$A:$A,Projections!K$4) -> 1.06 | L14: =IFERROR($G14*H13,0) -> 2.9201996 | M14: =IFERROR($G14*I13,0) -> 2.9201996 | N14: =IFERROR($G14*J13,0) -> 2.9495483 | O14: =IFERROR($G14*K13,0) -> 2.9495483 | P14: =_xlfn.XLOOKUP(B14,'2026'!A:A,'2026'!AS:AS) -> Weak | Q14: {=_xlfn.XLOOKUP(1, (Goalies!C:C=Projections!W14)*(Goalies!A:A=Projections!$Q$4), Goalies!D:D)} -> Connor Hellebuyck | R14: {=_xlfn.XLOOKUP(1, (Goalies!C:C=Projections!W14)*(Goalies!A:A=Projections!$R$4), Goalies!D:D)} -> Eric Comrie | S14: 1 | T14: =IFERROR(L14*S13+(1-S13)*N14,0) -> 2.9201996 | W14: =F14 -> WPG | X14: ='2026'!BJ12 -> 104 | Y14: ='2026'!BK12 -> 117 | Z14: ='2026'!BL12 -> -109 | AA14: ='2026'!BM12 -> -135
A15: =IF(D15=0,"0",(_xlfn.XLOOKUP(B15,'2026'!A:A,'2026'!C:C))) -> 46044 | B15: 2025020798 OTT | C15: 2025020798 | D15: =_xlfn.XLOOKUP(B15,'2026'!A:A,'2026'!AT:AT) -> 3.1218223 | E15: =_xlfn.XLOOKUP(B15,'2026'!A:A,'2026'!Z:Z) -> 1.02 | F15: =_xlfn.XLOOKUP(B15,'2026'!A:A,'2026'!E:E) -> OTT | G15: =D15/E16 -> 3.1503606 | H15: =SUMIFS(Goalies!$J:$J,Goalies!$C:$C,Projections!$F15,Goalies!$A:$A,Projections!H$2) -> 0.99 | I15: =SUMIFS(Goalies!$J:$J,Goalies!$C:$C,Projections!$F15,Goalies!$A:$A,Projections!I$2) -> 0.99 | J15: =SUMIFS(Goalies!$J:$J,Goalies!$C:$C,Projections!$F15,Goalies!$A:$A,Projections!J$2) -> 1.03 | K15: =SUMIFS(Goalies!$J:$J,Goalies!$C:$C,Projections!$F15,Goalies!$A:$A,Projections!K$2) -> 1.03 | L15: =IFERROR($G15*H16,0) -> 3.1218223 | M15: =IFERROR($G15*I16,0) -> 3.2133678 | N15: =IFERROR($G15*J16,0) -> 3.1218223 | O15: =IFERROR($G15*K16,0) -> 3.2133678 | P15: =_xlfn.XLOOKUP(B15,'2026'!A:A,'2026'!AS:AS) -> Neutral | Q15: {=_xlfn.XLOOKUP(1, (Goalies!C:C=Projections!W15)*(Goalies!A:A=Projections!$Q$4), Goalies!D:D)} -> Linus Ullmark | R15: {=_xlfn.XLOOKUP(1, (Goalies!C:C=Projections!W15)*(Goalies!A:A=Projections!$R$4), Goalies!D:D)} -> Leevi Merilainen | S15: 1 | T15: =IFERROR(L15*S16+(1-S16)*M15,0) -> 3.1218223 | W15: =F15 -> OTT | X15: ='2026'!BJ13 -> -109 | Y15: ='2026'!BK13 -> -140 | Z15: ='2026'!BL13 -> -113 | AA15: ='2026'!BM13 -> 113
A16: =IF(D16=0,"0",(_xlfn.XLOOKUP(B16,'2026'!A:A,'2026'!C:C))) -> 46044 | B16: 2025020798 NSH | C16: 2025020798 | D16: =_xlfn.XLOOKUP(B16,'2026'!A:A,'2026'!AT:AT) -> 3.1067255 | E16: =_xlfn.XLOOKUP(B16,'2026'!A:A,'2026'!Z:Z) -> 0.99094125 | F16: =_xlfn.XLOOKUP(B16,'2026'!A:A,'2026'!E:E) -> NSH | G16: =D16/E15 -> 3.0458094 | H16: =SUMIFS(Goalies!$J:$J,Goalies!$C:$C,Projections!$F16,Goalies!$A:$A,Projections!H$4) -> 0.99094125 | I16: =SUMIFS(Goalies!$J:$J,Goalies!$C:$C,Projections!$F16,Goalies!$A:$A,Projections!I$4) -> 1.02 | J16: =SUMIFS(Goalies!$J:$J,Goalies!$C:$C,Projections!$F16,Goalies!$A:$A,Projections!J$4) -> 0.99094125 | K16: =SUMIFS(Goalies!$J:$J,Goalies!$C:$C,Projections!$F16,Goalies!$A:$A,Projections!K$4) -> 1.02 | L16: =IFERROR($G16*H15,0) -> 3.0153513 | M16: =IFERROR($G16*I15,0) -> 3.0153513 | N16: =IFERROR($G16*J15,0) -> 3.1371836 | O16: =IFERROR($G16*K15,0) -> 3.1371836 | P16: =_xlfn.XLOOKUP(B16,'2026'!A:A,'2026'!AS:AS) -> Neutral | Q16: {=_xlfn.XLOOKUP(1, (Goalies!C:C=Projections!W16)*(Goalies!A:A=Projections!$Q$4), Goalies!D:D)} -> Juuse Saros | R16: {=_xlfn.XLOOKUP(1, (Goalies!C:C=Projections!W16)*(Goalies!A:A=Projections!$R$4), Goalies!D:D)} -> Justus Annunen | S16: 1 | T16: =IFERROR(L16*S15+(1-S15)*N16,0) -> 3.0153513 | W16: =F16 -> NSH | X16: ='2026'!BJ14 -> 109 | Y16: ='2026'!BK14 -> 140 | Z16: ='2026'!BL14 -> 113 | AA16: ='2026'!BM14 -> -113
A17: =IF(D17=0,"0",(_xlfn.XLOOKUP(B17,'2026'!A:A,'2026'!C:C))) -> 46044 | B17: 2025020800 PIT | C17: 2025020800 | D17: =_xlfn.XLOOKUP(B17,'2026'!A:A,'2026'!AT:AT) -> 2.7898263 | E17: =_xlfn.XLOOKUP(B17,'2026'!A:A,'2026'!Z:Z) -> 1.03 | F17: =_xlfn.XLOOKUP(B17,'2026'!A:A,'2026'!E:E) -> PIT | G17: =D17/E18 -> 2.8613603 | H17: =SUMIFS(Goalies!$J:$J,Goalies!$C:$C,Projections!$F17,Goalies!$A:$A,Projections!H$2) -> 0.975 | I17: =SUMIFS(Goalies!$J:$J,Goalies!$C:$C,Projections!$F17,Goalies!$A:$A,Projections!I$2) -> 0.975 | J17: =SUMIFS(Goalies!$J:$J,Goalies!$C:$C,Projections!$F17,Goalies!$A:$A,Projections!J$2) -> 2.07 | K17: =SUMIFS(Goalies!$J:$J,Goalies!$C:$C,Projections!$F17,Goalies!$A:$A,Projections!K$2) -> 2.07 | L17: =IFERROR($G17*H18,0) -> 2.7898263 | M17: =IFERROR($G17*I18,0) -> 2.9472011 | N17: =IFERROR($G17*J18,0) -> 2.7898263 | O17: =IFERROR($G17*K18,0) -> 2.9472011 | P17: =_xlfn.XLOOKUP(B17,'2026'!A:A,'2026'!AS:AS) -> Neutral | Q17: {=_xlfn.XLOOKUP(1, (Goalies!C:C=Projections!W17)*(Goalies!A:A=Projections!$Q$4), Goalies!D:D)} -> Stuart Skinner | R17: {=_xlfn.XLOOKUP(1, (Goalies!C:C=Projections!W17)*(Goalies!A:A=Projections!$R$4), Goalies!D:D)} -> Arturs Silovs | S17: 1 | T17: =IFERROR(L17*S18+(1-S18)*M17,0) -> 2.7898263 | W17: =F17 -> PIT | X17: ='2026'!BJ15 -> 157 | Y17: ='2026'!BK15 -> -153 | Z17: ='2026'!BL15 -> -124 | AA17: ='2026'!BM15 -> 104
A18: =IF(D18=0,"0",(_xlfn.XLOOKUP(B18,'2026'!A:A,'2026'!C:C))) -> 46044 | B18: 2025020800 EDM | C18: 2025020800 | D18: =_xlfn.XLOOKUP(B18,'2026'!A:A,'2026'!AT:AT) -> 3.6919052 | E18: =_xlfn.XLOOKUP(B18,'2026'!A:A,'2026'!Z:Z) -> 0.975 | F18: =_xlfn.XLOOKUP(B18,'2026'!A:A,'2026'!E:E) -> EDM | G18: =D18/E17 -> 3.584374 | H18: =SUMIFS(Goalies!$J:$J,Goalies!$C:$C,Projections!$F18,Goalies!$A:$A,Projections!H$4) -> 0.975 | I18: =SUMIFS(Goalies!$J:$J,Goalies!$C:$C,Projections!$F18,Goalies!$A:$A,Projections!I$4) -> 1.03 | J18: =SUMIFS(Goalies!$J:$J,Goalies!$C:$C,Projections!$F18,Goalies!$A:$A,Projections!J$4) -> 0.975 | K18: =SUMIFS(Goalies!$J:$J,Goalies!$C:$C,Projections!$F18,Goalies!$A:$A,Projections!K$4) -> 1.03 | L18: =IFERROR($G18*H17,0) -> 3.4947646 | M18: =IFERROR($G18*I17,0) -> 3.4947646 | N18: =IFERROR($G18*J17,0) -> 7.4196541 | O18: =IFERROR($G18*K17,0) -> 7.4196541 | P18: =_xlfn.XLOOKUP(B18,'2026'!A:A,'2026'!AS:AS) -> Neutral | Q18: {=_xlfn.XLOOKUP(1, (Goalies!C:C=Projections!W18)*(Goalies!A:A=Projections!$Q$4), Goalies!D:D)} -> Tristan Jarry | R18: {=_xlfn.XLOOKUP(1, (Goalies!C:C=Projections!W18)*(Goalies!A:A=Projections!$R$4), Goalies!D:D)} -> Calvin Pickard | S18: 1 | T18: =IFERROR(L18*S17+(1-S17)*N18,0) -> 3.4947646 | W18: =F18 -> EDM | X18: ='2026'!BJ16 -> -157 | Y18: ='2026'!BK16 -> 153 | Z18: ='2026'!BL16 -> 124 | AA18: ='2026'!BM16 -> -104
A19: =IF(D19=0,"0",(_xlfn.XLOOKUP(B19,'2026'!A:A,'2026'!C:C))) -> 46044 | B19: 2025020801 DET | C19: 2025020801 | D19: =_xlfn.XLOOKUP(B19,'2026'!A:A,'2026'!AT:AT) -> 2.7730591 | E19: =_xlfn.XLOOKUP(B19,'2026'!A:A,'2026'!Z:Z) -> 1.01 | F19: =_xlfn.XLOOKUP(B19,'2026'!A:A,'2026'!E:E) -> DET | G19: =D19/E20 -> 2.8010698 | H19: =SUMIFS(Goalies!$J:$J,Goalies!$C:$C,Projections!$F19,Goalies!$A:$A,Projections!H$2) -> 0.99 | I19: =SUMIFS(Goalies!$J:$J,Goalies!$C:$C,Projections!$F19,Goalies!$A:$A,Projections!I$2) -> 0.99 | J19: =SUMIFS(Goalies!$J:$J,Goalies!$C:$C,Projections!$F19,Goalies!$A:$A,Projections!J$2) -> 1.01 | K19: =SUMIFS(Goalies!$J:$J,Goalies!$C:$C,Projections!$F19,Goalies!$A:$A,Projections!K$2) -> 1.01 | L19: =IFERROR($G19*H20,0) -> 2.7730591 | M19: =IFERROR($G19*I20,0) -> 2.8430858 | N19: =IFERROR($G19*J20,0) -> 2.7730591 | O19: =IFERROR($G19*K20,0) -> 2.8430858 | P19: =_xlfn.XLOOKUP(B19,'2026'!A:A,'2026'!AS:AS) -> Neutral | Q19: {=_xlfn.XLOOKUP(1, (Goalies!C:C=Projections!W19)*(Goalies!A:A=Projections!$Q$4), Goalies!D:D)} -> John Gibson | R19: {=_xlfn.XLOOKUP(1, (Goalies!C:C=Projections!W19)*(Goalies!A:A=Projections!$R$4), Goalies!D:D)} -> Cam Talbot | S19: 1 | T19: =IFERROR(L19*S20+(1-S20)*M19,0) -> 2.7730591 | W19: =F19 -> DET | X19: ='2026'!BJ17 -> 140 | Y19: ='2026'!BK17 -> -132 | Z19: ='2026'!BL17 -> -106 | AA19: ='2026'!BM17 -> 119
A20: =IF(D20=0,"0",(_xlfn.XLOOKUP(B20,'2026'!A:A,'2026'!C:C))) -> 46044 | B20: 2025020801 MIN | C20: 2025020801 | D20: =_xlfn.XLOOKUP(B20,'2026'!A:A,'2026'!AT:AT) -> 3.3520379 | E20: =_xlfn.XLOOKUP(B20,'2026'!A:A,'2026'!Z:Z) -> 0.99 | F20: =_xlfn.XLOOKUP(B20,'2026'!A:A,'2026'!E:E) -> MIN | G20: =D20/E19 -> 3.3188494 | H20: =SUMIFS(Goalies!$J:$J,Goalies!$C:$C,Projections!$F20,Goalies!$A:$A,Projections!H$4) -> 0.99 | I20: =SUMIFS(Goalies!$J:$J,Goalies!$C:$C,Projections!$F20,Goalies!$A:$A,Projections!I$4) -> 1.015 | J20: =SUMIFS(Goalies!$J:$J,Goalies!$C:$C,Projections!$F20,Goalies!$A:$A,Projections!J$4) -> 0.99 | K20: =SUMIFS(Goalies!$J:$J,Goalies!$C:$C,Projections!$F20,Goalies!$A:$A,Projections!K$4) -> 1.015 | L20: =IFERROR($G20*H19,0) -> 3.2856609 | M20: =IFERROR($G20*I19,0) -> 3.2856609 | N20: =IFERROR($G20*J19,0) -> 3.3520379 | O20: =IFERROR($G20*K19,0) -> 3.3520379 | P20: =_xlfn.XLOOKUP(B20,'2026'!A:A,'2026'!AS:AS) -> Neutral | Q20: {=_xlfn.XLOOKUP(1, (Goalies!C:C=Projections!W20)*(Goalies!A:A=Projections!$Q$4), Goalies!D:D)} -> Filip Gustavsson | R20: {=_xlfn.XLOOKUP(1, (Goalies!C:C=Projections!W20)*(Goalies!A:A=Projections!$R$4), Goalies!D:D)} -> Jesper Wallstedt | S20: 1 | T20: =IFERROR(L20*S19+(1-S19)*N20,0) -> 3.2856609 | W20: =F20 -> MIN | X20: ='2026'!BJ18 -> -140 | Y20: ='2026'!BK18 -> 132 | Z20: ='2026'!BL18 -> 106 | AA20: ='2026'!BM18 -> -119
A21: =IF(D21=0,"0",(_xlfn.XLOOKUP(B21,'2026'!A:A,'2026'!C:C))) -> 46045 | B21: 2025020803 TBL | C21: 2025020803 | D21: =_xlfn.XLOOKUP(B21,'2026'!A:A,'2026'!AT:AT) -> 4.0631841 | E21: =_xlfn.XLOOKUP(B21,'2026'!A:A,'2026'!Z:Z) -> 0.965 | F21: =_xlfn.XLOOKUP(B21,'2026'!A:A,'2026'!E:E) -> TBL | G21: =D21/E22 -> 3.8331926 | H21: =SUMIFS(Goalies!$J:$J,Goalies!$C:$C,Projections!$F21,Goalies!$A:$A,Projections!H$2) -> 0.965 | I21: =SUMIFS(Goalies!$J:$J,Goalies!$C:$C,Projections!$F21,Goalies!$A:$A,Projections!I$2) -> 0.965 | J21: =SUMIFS(Goalies!$J:$J,Goalies!$C:$C,Projections!$F21,Goalies!$A:$A,Projections!J$2) -> 1.05 | K21: =SUMIFS(Goalies!$J:$J,Goalies!$C:$C,Projections!$F21,Goalies!$A:$A,Projections!K$2) -> 1.05 | L21: =IFERROR($G21*H22,0) -> 3.6798649 | M21: =IFERROR($G21*I22,0) -> 4.0631841 | N21: =IFERROR($G21*J22,0) -> 3.6798649 | O21: =IFERROR($G21*K22,0) -> 4.0631841 | P21: =_xlfn.XLOOKUP(B21,'2026'!A:A,'2026'!AS:AS) -> Neutral | Q21: {=_xlfn.XLOOKUP(1, (Goalies!C:C=Projections!W21)*(Goalies!A:A=Projections!$Q$4), Goalies!D:D)} -> Andrei Vasilevskiy | R21: {=_xlfn.XLOOKUP(1, (Goalies!C:C=Projections!W21)*(Goalies!A:A=Projections!$R$4), Goalies!D:D)} -> Jonas Johansson | S21: 1 | T21: =IFERROR(L21*S22+(1-S22)*M21,0) -> 4.0631841 | W21: =F21 -> TBL | X21: ='2026'!BJ19 -> -279 | Y21: ='2026'!BK19 -> -174 | Z21: ='2026'!BL19 -> -141 | AA21: ='2026'!BM19 -> -107
A22: =IF(D22=0,"0",(_xlfn.XLOOKUP(B22,'2026'!A:A,'2026'!C:C))) -> 46045 | B22: 2025020803 CHI | C22: 2025020803 | D22: =_xlfn.XLOOKUP(B22,'2026'!A:A,'2026'!AT:AT) -> 2.4124869 | E22: =_xlfn.XLOOKUP(B22,'2026'!A:A,'2026'!Z:Z) -> 1.06 | F22: =_xlfn.XLOOKUP(B22,'2026'!A:A,'2026'!E:E) -> CHI | G22: =D22/E21 -> 2.4999864 | H22: =SUMIFS(Goalies!$J:$J,Goalies!$C:$C,Projections!$F22,Goalies!$A:$A,Projections!H$4) -> 0.96 | I22: =SUMIFS(Goalies!$J:$J,Goalies!$C:$C,Projections!$F22,Goalies!$A:$A,Projections!I$4) -> 1.06 | J22: =SUMIFS(Goalies!$J:$J,Goalies!$C:$C,Projections!$F22,Goalies!$A:$A,Projections!J$4) -> 0.96 | K22: =SUMIFS(Goalies!$J:$J,Goalies!$C:$C,Projections!$F22,Goalies!$A:$A,Projections!K$4) -> 1.06 | L22: =IFERROR($G22*H21,0) -> 2.4124869 | M22: =IFERROR($G22*I21,0) -> 2.4124869 | N22: =IFERROR($G22*J21,0) -> 2.6249857 | O22: =IFERROR($G22*K21,0) -> 2.6249857 | P22: =_xlfn.XLOOKUP(B22,'2026'!A:A,'2026'!AS:AS) -> Neutral | Q22: {=_xlfn.XLOOKUP(1, (Goalies!C:C=Projections!W22)*(Goalies!A:A=Projections!$Q$4), Goalies!D:D)} -> Spencer Knight | R22: {=_xlfn.XLOOKUP(1, (Goalies!C:C=Projections!W22)*(Goalies!A:A=Projections!$R$4), Goalies!D:D)} -> Arvid Soderblom | S22: 0 | T22: =IFERROR(L22*S21+(1-S21)*N22,0) -> 2.4124869 | W22: =F22 -> CHI | X22: ='2026'!BJ20 -> 279 | Y22: ='2026'!BK20 -> 174 | Z22: ='2026'!BL20 -> 141 | AA22: ='2026'!BM20 -> 107
A23: =IF(D23=0,"0",(_xlfn.XLOOKUP(B23,'2026'!A:A,'2026'!C:C))) -> 46045 | B23: 2025020802 VGK | C23: 2025020802 | D23: =_xlfn.XLOOKUP(B23,'2026'!A:A,'2026'!AT:AT) -> 3.0383879 | E23: =_xlfn.XLOOKUP(B23,'2026'!A:A,'2026'!Z:Z) -> 1 | F23: =_xlfn.XLOOKUP(B23,'2026'!A:A,'2026'!E:E) -> VGK | G23: =D23/E24 -> 3.1323587 | H23: =SUMIFS(Goalies!$J:$J,Goalies!$C:$C,Projections!$F23,Goalies!$A:$A,Projections!H$2) -> 1 | I23: =SUMIFS(Goalies!$J:$J,Goalies!$C:$C,Projections!$F23,Goalies!$A:$A,Projections!I$2) -> 1 | J23: =SUMIFS(Goalies!$J:$J,Goalies!$C:$C,Projections!$F23,Goalies!$A:$A,Projections!J$2) -> 2.04 | K23: =SUMIFS(Goalies!$J:$J,Goalies!$C:$C,Projections!$F23,Goalies!$A:$A,Projections!K$2) -> 2.04 | L23: =IFERROR($G23*H24,0) -> 3.1636823 | M23: =IFERROR($G23*I24,0) -> 3.0383879 | N23: =IFERROR($G23*J24,0) -> 3.1636823 | O23: =IFERROR($G23*K24,0) -> 3.0383879 | P23: =_xlfn.XLOOKUP(B23,'2026'!A:A,'2026'!AS:AS) -> Neutral | Q23: {=_xlfn.XLOOKUP(1, (Goalies!C:C=Projections!W23)*(Goalies!A:A=Projections!$Q$4), Goalies!D:D)} -> Adin Hill | R23: {=_xlfn.XLOOKUP(1, (Goalies!C:C=Projections!W23)*(Goalies!A:A=Projections!$R$4), Goalies!D:D)} -> Akira Schmid | S23: 1 | T23: =IFERROR(L23*S24+(1-S24)*M23,0) -> 3.1636823 | W23: =F23 -> VGK | X23: ='2026'!BJ21 -> -113 | Y23: ='2026'!BK21 -> -142 | Z23: ='2026'!BL21 -> -115 | AA23: ='2026'!BM21 -> 111
A24: =IF(D24=0,"0",(_xlfn.XLOOKUP(B24,'2026'!A:A,'2026'!C:C))) -> 46045 | B24: 2025020802 TOR | C24: 2025020802 | D24: =_xlfn.XLOOKUP(B24,'2026'!A:A,'2026'!AT:AT) -> 2.9991725 | E24: =_xlfn.XLOOKUP(B24,'2026'!A:A,'2026'!Z:Z) -> 0.97 | F24: =_xlfn.XLOOKUP(B24,'2026'!A:A,'2026'!E:E) -> TOR | G24: =D24/E23 -> 2.9991725 | H24: =SUMIFS(Goalies!$J:$J,Goalies!$C:$C,Projections!$F24,Goalies!$A:$A,Projections!H$4) -> 1.01 | I24: =SUMIFS(Goalies!$J:$J,Goalies!$C:$C,Projections!$F24,Goalies!$A:$A,Projections!I$4) -> 0.97 | J24: =SUMIFS(Goalies!$J:$J,Goalies!$C:$C,Projections!$F24,Goalies!$A:$A,Projections!J$4) -> 1.01 | K24: =SUMIFS(Goalies!$J:$J,Goalies!$C:$C,Projections!$F24,Goalies!$A:$A,Projections!K$4) -> 0.97 | L24: =IFERROR($G24*H23,0) -> 2.9991725 | M24: =IFERROR($G24*I23,0) -> 2.9991725 | N24: =IFERROR($G24*J23,0) -> 6.1183118 | O24: =IFERROR($G24*K23,0) -> 6.1183118 | P24: =_xlfn.XLOOKUP(B24,'2026'!A:A,'2026'!AS:AS) -> Neutral | Q24: {=_xlfn.XLOOKUP(1, (Goalies!C:C=Projections!W24)*(Goalies!A:A=Projections!$Q$4), Goalies!D:D)} -> Anthony Stolarz | R24: {=_xlfn.XLOOKUP(1, (Goalies!C:C=Projections!W24)*(Goalies!A:A=Projections!$R$4), Goalies!D:D)} -> Joseph Woll | S24: 1 | T24: =IFERROR(L24*S23+(1-S23)*N24,0) -> 2.9991725 | W24: =F24 -> TOR | X24: ='2026'!BJ22 -> 113 | Y24: ='2026'!BK22 -> 142 | Z24: ='2026'!BL22 -> 115 | AA24: ='2026'!BM22 -> -111
A25: =IF(D25=0,"0",(_xlfn.XLOOKUP(B25,'2026'!A:A,'2026'!C:C))) -> 46045 | B25: 2025020804 STL | C25: 2025020804 | D25: =_xlfn.XLOOKUP(B25,'2026'!A:A,'2026'!AT:AT) -> 2.6116437 | E25: =_xlfn.XLOOKUP(B25,'2026'!A:A,'2026'!Z:Z) -> 0.98 | F25: =_xlfn.XLOOKUP(B25,'2026'!A:A,'2026'!E:E) -> STL | G25: =D25/E26 -> 2.6247676 | H25: =SUMIFS(Goalies!$J:$J,Goalies!$C:$C,Projections!$F25,Goalies!$A:$A,Projections!H$2) -> 1.02 | I25: =SUMIFS(Goalies!$J:$J,Goalies!$C:$C,Projections!$F25,Goalies!$A:$A,Projections!I$2) -> 1.02 | J25: =SUMIFS(Goalies!$J:$J,Goalies!$C:$C,Projections!$F25,Goalies!$A:$A,Projections!J$2) -> 0.98 | K25: =SUMIFS(Goalies!$J:$J,Goalies!$C:$C,Projections!$F25,Goalies!$A:$A,Projections!K$2) -> 0.98 | L25: =IFERROR($G25*H26,0) -> 2.6116437 | M25: =IFERROR($G25*I26,0) -> 2.6378914 | N25: =IFERROR($G25*J26,0) -> 2.6116437 | O25: =IFERROR($G25*K26,0) -> 2.6378914 | P25: =_xlfn.XLOOKUP(B25,'2026'!A:A,'2026'!AS:AS) -> Weak | Q25: {=_xlfn.XLOOKUP(1, (Goalies!C:C=Projections!W25)*(Goalies!A:A=Projections!$Q$4), Goalies!D:D)} -> Jordan Binnington | R25: {=_xlfn.XLOOKUP(1, (Goalies!C:C=Projections!W25)*(Goalies!A:A=Projections!$R$4), Goalies!D:D)} -> Joel Hofer | S25: 1 | T25: =IFERROR(L25*S26+(1-S26)*M25,0) -> 2.6116437 | W25: =F25 -> STL | X25: ='2026'!BJ23 -> 165 | Y25: ='2026'!BK23 -> -127 | Z25: ='2026'!BL23 -> -100 | AA25: ='2026'!BM23 -> 126
A26: =IF(D26=0,"0",(_xlfn.XLOOKUP(B26,'2026'!A:A,'2026'!C:C))) -> 46045 | B26: 2025020804 DAL | C26: 2025020804 | D26: =_xlfn.XLOOKUP(B26,'2026'!A:A,'2026'!AT:AT) -> 3.2428629 | E26: =_xlfn.XLOOKUP(B26,'2026'!A:A,'2026'!Z:Z) -> 0.995 | F26: =_xlfn.XLOOKUP(B26,'2026'!A:A,'2026'!E:E) -> DAL | G26: =D26/E25 -> 3.3090437 | H26: =SUMIFS(Goalies!$J:$J,Goalies!$C:$C,Projections!$F26,Goalies!$A:$A,Projections!H$4) -> 0.995 | I26: =SUMIFS(Goalies!$J:$J,Goalies!$C:$C,Projections!$F26,Goalies!$A:$A,Projections!I$4) -> 1.005 | J26: =SUMIFS(Goalies!$J:$J,Goalies!$C:$C,Projections!$F26,Goalies!$A:$A,Projections!J$4) -> 0.995 | K26: =SUMIFS(Goalies!$J:$J,Goalies!$C:$C,Projections!$F26,Goalies!$A:$A,Projections!K$4) -> 1.005 | L26: =IFERROR($G26*H25,0) -> 3.3752246 | M26: =IFERROR($G26*I25,0) -> 3.3752246 | N26: =IFERROR($G26*J25,0) -> 3.2428629 | O26: =IFERROR($G26*K25,0) -> 3.2428629 | P26: =_xlfn.XLOOKUP(B26,'2026'!A:A,'2026'!AS:AS) -> Weak | Q26: {=_xlfn.XLOOKUP(1, (Goalies!C:C=Projections!W26)*(Goalies!A:A=Projections!$Q$4), Goalies!D:D)} -> Jake Oettinger | R26: {=_xlfn.XLOOKUP(1, (Goalies!C:C=Projections!W26)*(Goalies!A:A=Projections!$R$4), Goalies!D:D)} -> Casey DeSmith | S26: 1 | T26: =IFERROR(L26*S25+(1-S25)*N26,0) -> 3.3752246 | W26: =F26 -> DAL | X26: ='2026'!BJ24 -> -165 | Y26: ='2026'!BK24 -> 127 | Z26: ='2026'!BL24 -> 100 | AA26: ='2026'!BM24 -> -126
A27: =IF(D27=0,"0",(_xlfn.XLOOKUP(B27,'2026'!A:A,'2026'!C:C))) -> 46045 | B27: 2025020805 PHI | C27: 2025020805 | D27: =_xlfn.XLOOKUP(B27,'2026'!A:A,'2026'!AT:AT) -> 2.2706318 | E27: =_xlfn.XLOOKUP(B27,'2026'!A:A,'2026'!Z:Z) -> 1 | F27: =_xlfn.XLOOKUP(B27,'2026'!A:A,'2026'!E:E) -> PHI | G27: =D27/E28 -> 2.2935675 | H27: =SUMIFS(Goalies!$J:$J,Goalies!$C:$C,Projections!$F27,Goalies!$A:$A,Projections!H$2) -> 1.04 | I27: =SUMIFS(Goalies!$J:$J,Goalies!$C:$C,Projections!$F27,Goalies!$A:$A,Projections!I$2) -> 1.04 | J27: =SUMIFS(Goalies!$J:$J,Goalies!$C:$C,Projections!$F27,Goalies!$A:$A,Projections!J$2) -> 2.035 | K27: =SUMIFS(Goalies!$J:$J,Goalies!$C:$C,Projections!$F27,Goalies!$A:$A,Projections!K$2) -> 2.035 | L27: =IFERROR($G27*H28,0) -> 2.2706318 | M27: =IFERROR($G27*I28,0) -> 2.3165032 | N27: =IFERROR($G27*J28,0) -> 2.2706318 | O27: =IFERROR($G27*K28,0) -> 2.3165032 | P27: =_xlfn.XLOOKUP(B27,'2026'!A:A,'2026'!AS:AS) -> Neutral | Q27: {=_xlfn.XLOOKUP(1, (Goalies!C:C=Projections!W27)*(Goalies!A:A=Projections!$Q$4), Goalies!D:D)} -> Samuel Ersson | R27: {=_xlfn.XLOOKUP(1, (Goalies!C:C=Projections!W27)*(Goalies!A:A=Projections!$R$4), Goalies!D:D)} -> Dan Vladar | S27: 1 | T27: =IFERROR(L27*S28+(1-S28)*M27,0) -> 2.2706318 | W27: =F27 -> PHI | X27: ='2026'!BJ25 -> 322 | Y27: ='2026'!BK25 -> -165 | Z27: ='2026'!BL25 -> -133 | AA27: ='2026'!BM25 -> -100
A28: =IF(D28=0,"0",(_xlfn.XLOOKUP(B28,'2026'!A:A,'2026'!C:C))) -> 46045 | B28: 2025020805 COL | C28: 2025020805 | D28: =_xlfn.XLOOKUP(B28,'2026'!A:A,'2026'!AT:AT) -> 3.9696174 | E28: =_xlfn.XLOOKUP(B28,'2026'!A:A,'2026'!Z:Z) -> 0.99 | F28: =_xlfn.XLOOKUP(B28,'2026'!A:A,'2026'!E:E) -> COL | G28: =D28/E27 -> 3.9696174 | H28: =SUMIFS(Goalies!$J:$J,Goalies!$C:$C,Projections!$F28,Goalies!$A:$A,Projections!H$4) -> 0.99 | I28: =SUMIFS(Goalies!$J:$J,Goalies!$C:$C,Projections!$F28,Goalies!$A:$A,Projections!I$4) -> 1.01 | J28: =SUMIFS(Goalies!$J:$J,Goalies!$C:$C,Projections!$F28,Goalies!$A:$A,Projections!J$4) -> 0.99 | K28: =SUMIFS(Goalies!$J:$J,Goalies!$C:$C,Projections!$F28,Goalies!$A:$A,Projections!K$4) -> 1.01 | L28: =IFERROR($G28*H27,0) -> 4.128402 | M28: =IFERROR($G28*I27,0) -> 4.128402 | N28: =IFERROR($G28*J27,0) -> 8.0781713 | O28: =IFERROR($G28*K27,0) -> 8.0781713 | P28: =_xlfn.XLOOKUP(B28,'2026'!A:A,'2026'!AS:AS) -> Neutral | Q28: {=_xlfn.XLOOKUP(1, (Goalies!C:C=Projections!W28)*(Goalies!A:A=Projections!$Q$4), Goalies!D:D)} -> Mackenzie Blackwood | R28: {=_xlfn.XLOOKUP(1, (Goalies!C:C=Projections!W28)*(Goalies!A:A=Projections!$R$4), Goalies!D:D)} -> Scott Wedgewood | S28: 1 | T28: =IFERROR(L28*S27+(1-S27)*N28,0) -> 4.128402 | W28: =F28 -> COL | X28: ='2026'!BJ26 -> -322 | Y28: ='2026'!BK26 -> 165 | Z28: ='2026'!BL26 -> 133 | AA28: ='2026'!BM26 -> 100
A29: =IF(D29=0,"0",(_xlfn.XLOOKUP(B29,'2026'!A:A,'2026'!C:C))) -> 46045 | B29: 2025020806 WSH | C29: 2025020806 | D29: =_xlfn.XLOOKUP(B29,'2026'!A:A,'2026'!AT:AT) -> 3.1411337 | E29: =_xlfn.XLOOKUP(B29,'2026'!A:A,'2026'!Z:Z) -> 1 | F29: =_xlfn.XLOOKUP(B29,'2026'!A:A,'2026'!E:E) -> WSH | G29: =D29/E30 -> 3.1889683 | H29: =SUMIFS(Goalies!$J:$J,Goalies!$C:$C,Projections!$F29,Goalies!$A:$A,Projections!H$2) -> 0.975 | I29: =SUMIFS(Goalies!$J:$J,Goalies!$C:$C,Projections!$F29,Goalies!$A:$A,Projections!I$2) -> 0.975 | J29: =SUMIFS(Goalies!$J:$J,Goalies!$C:$C,Projections!$F29,Goalies!$A:$A,Projections!J$2) -> 1.04 | K29: =SUMIFS(Goalies!$J:$J,Goalies!$C:$C,Projections!$F29,Goalies!$A:$A,Projections!K$2) -> 1.04 | L29: =IFERROR($G29*H30,0) -> 3.1411337 | M29: =IFERROR($G29*I30,0) -> 3.2527476 | N29: =IFERROR($G29*J30,0) -> 3.1411337 | O29: =IFERROR($G29*K30,0) -> 3.2527476 | P29: =_xlfn.XLOOKUP(B29,'2026'!A:A,'2026'!AS:AS) -> Neutral | Q29: {=_xlfn.XLOOKUP(1, (Goalies!C:C=Projections!W29)*(Goalies!A:A=Projections!$Q$4), Goalies!D:D)} -> Logan Thompson | R29: {=_xlfn.XLOOKUP(1, (Goalies!C:C=Projections!W29)*(Goalies!A:A=Projections!$R$4), Goalies!D:D)} -> Charlie Lindgren | S29: 1 | T29: =IFERROR(L29*S28+(1-S28)*N29,0) -> 3.1411337 | W29: =F29 -> WSH | X29: ='2026'!BJ27 -> -131 | Y29: ='2026'!BK27 -> -120 | Z29: ='2026'!BL27 -> 105 | AA29: ='2026'!BM27 -> 132
A30: =IF(D30=0,"0",(_xlfn.XLOOKUP(B30,'2026'!A:A,'2026'!C:C))) -> 46045 | B30: 2025020806 CGY | C30: 2025020806 | D30: =_xlfn.XLOOKUP(B30,'2026'!A:A,'2026'!AT:AT) -> 2.8246762 | E30: =_xlfn.XLOOKUP(B30,'2026'!A:A,'2026'!Z:Z) -> 0.985 | F30: =_xlfn.XLOOKUP(B30,'2026'!A:A,'2026'!E:E) -> CGY | G30: =D30/E29 -> 2.8246762 | H30: =SUMIFS(Goalies!$J:$J,Goalies!$C:$C,Projections!$F30,Goalies!$A:$A,Projections!H$4) -> 0.985 | I30: =SUMIFS(Goalies!$J:$J,Goalies!$C:$C,Projections!$F30,Goalies!$A:$A,Projections!I$4) -> 1.02 | J30: =SUMIFS(Goalies!$J:$J,Goalies!$C:$C,Projections!$F30,Goalies!$A:$A,Projections!J$4) -> 0.985 | K30: =SUMIFS(Goalies!$J:$J,Goalies!$C:$C,Projections!$F30,Goalies!$A:$A,Projections!K$4) -> 1.02 | L30: =IFERROR($G30*H29,0) -> 2.7540593 | M30: =IFERROR($G30*I29,0) -> 2.7540593 | N30: =IFERROR($G30*J29,0) -> 2.9376633 | O30: =IFERROR($G30*K29,0) -> 2.9376633 | P30: =_xlfn.XLOOKUP(B30,'2026'!A:A,'2026'!AS:AS) -> Neutral | Q30: {=_xlfn.XLOOKUP(1, (Goalies!C:C=Projections!W30)*(Goalies!A:A=Projections!$Q$4), Goalies!D:D)} -> Dustin Wolf | R30: {=_xlfn.XLOOKUP(1, (Goalies!C:C=Projections!W30)*(Goalies!A:A=Projections!$R$4), Goalies!D:D)} -> Devin Cooley | S30: 1 | T30: =IFERROR(L30*S29+(1-S29)*N30,0) -> 2.7540593 | W30: =F30 -> CGY | X30: ='2026'!BJ28 -> 131 | Y30: ='2026'!BK28 -> 120 | Z30: ='2026'!BL28 -> -105 | AA30: ='2026'!BM28 -> -132
A31: =IF(D31=0,"0",(_xlfn.XLOOKUP(B31,'2026'!A:A,'2026'!C:C))) -> 46045 | B31: 2025020809 ANA | C31: 2025020809 | D31: =_xlfn.XLOOKUP(B31,'2026'!A:A,'2026'!AT:AT) -> 3.0174082 | E31: =_xlfn.XLOOKUP(B31,'2026'!A:A,'2026'!Z:Z) -> 0.97 | F31: =_xlfn.XLOOKUP(B31,'2026'!A:A,'2026'!E:E) -> ANA | G31: =D31/E32 -> 3.0174082 | H31: =SUMIFS(Goalies!$J:$J,Goalies!$C:$C,Projections!$F31,Goalies!$A:$A,Projections!H$2) -> 0.97 | I31: =SUMIFS(Goalies!$J:$J,Goalies!$C:$C,Projections!$F31,Goalies!$A:$A,Projections!I$2) -> 0.97 | J31: =SUMIFS(Goalies!$J:$J,Goalies!$C:$C,Projections!$F31,Goalies!$A:$A,Projections!J$2) -> 2.085 | K31: =SUMIFS(Goalies!$J:$J,Goalies!$C:$C,Projections!$F31,Goalies!$A:$A,Projections!K$2) -> 2.085 | L31: =IFERROR($G31*H32,0) -> 3.0174082 | M31: =IFERROR($G31*I32,0) -> 3.0174082 | N31: =IFERROR($G31*J32,0) -> 3.0174082 | O31: =IFERROR($G31*K32,0) -> 3.0174082 | P31: =_xlfn.XLOOKUP(B31,'2026'!A:A,'2026'!AS:AS) -> Neutral | Q31: {=_xlfn.XLOOKUP(1, (Goalies!C:C=Projections!W31)*(Goalies!A:A=Projections!$Q$4), Goalies!D:D)} -> Lukas Dostal | R31: {=_xlfn.XLOOKUP(1, (Goalies!C:C=Projections!W31)*(Goalies!A:A=Projections!$R$4), Goalies!D:D)} -> Petr Mrazek | S31: 0 | T31: =IFERROR(L31*S32+(1-S32)*M31,0) -> 3.0174082 | W31: =F31 -> ANA | X31: ='2026'!BJ29 -> #N/A | Y31: ='2026'!BK29 -> #N/A | Z31: ='2026'!BL29 -> #N/A | AA31: ='2026'!BM29 -> #N/A
A32: =IF(D32=0,"0",(_xlfn.XLOOKUP(B32,'2026'!A:A,'2026'!C:C))) -> 46045 | B32: 2025020809 SEA | C32: 2025020809 | D32: =_xlfn.XLOOKUP(B32,'2026'!A:A,'2026'!AT:AT) -> 3.0130659 | E32: =_xlfn.XLOOKUP(B32,'2026'!A:A,'2026'!Z:Z) -> 1 | F32: =_xlfn.XLOOKUP(B32,'2026'!A:A,'2026'!E:E) -> SEA | G32: =D32/E31 -> 3.1062536 | H32: =SUMIFS(Goalies!$J:$J,Goalies!$C:$C,Projections!$F32,Goalies!$A:$A,Projections!H$4) -> 1 | I32: =SUMIFS(Goalies!$J:$J,Goalies!$C:$C,Projections!$F32,Goalies!$A:$A,Projections!I$4) -> 1 | J32: =SUMIFS(Goalies!$J:$J,Goalies!$C:$C,Projections!$F32,Goalies!$A:$A,Projections!J$4) -> 1 | K32: =SUMIFS(Goalies!$J:$J,Goalies!$C:$C,Projections!$F32,Goalies!$A:$A,Projections!K$4) -> 1 | L32: =IFERROR($G32*H31,0) -> 3.0130659 | M32: =IFERROR($G32*I31,0) -> 3.0130659 | N32: =IFERROR($G32*J31,0) -> 6.4765387 | O32: =IFERROR($G32*K31,0) -> 6.4765387 | P32: =_xlfn.XLOOKUP(B32,'2026'!A:A,'2026'!AS:AS) -> Neutral | Q32: {=_xlfn.XLOOKUP(1, (Goalies!C:C=Projections!W32)*(Goalies!A:A=Projections!$Q$4), Goalies!D:D)} -> Joey Daccord | R32: {=_xlfn.XLOOKUP(1, (Goalies!C:C=Projections!W32)*(Goalies!A:A=Projections!$R$4), Goalies!D:D)} -> Philipp Grubauer | S32: 1 | T32: =IFERROR(L32*S31+(1-S31)*N32,0) -> 6.4765387 | W32: =F32 -> SEA | X32: ='2026'!BJ30 -> #N/A | Y32: ='2026'!BK30 -> #N/A | Z32: ='2026'!BL30 -> #N/A | AA32: ='2026'!BM30 -> #N/A
A33: =IF(D33=0,"0",(_xlfn.XLOOKUP(B33,'2026'!A:A,'2026'!C:C))) -> 46045 | B33: 2025020807 NJD | C33: 2025020807 | D33: =_xlfn.XLOOKUP(B33,'2026'!A:A,'2026'!AT:AT) -> 3.287251 | E33: =_xlfn.XLOOKUP(B33,'2026'!A:A,'2026'!Z:Z) -> 1.02 | F33: =_xlfn.XLOOKUP(B33,'2026'!A:A,'2026'!E:E) -> NJD | G33: =D33/E34 -> 3.1915058 | H33: =SUMIFS(Goalies!$J:$J,Goalies!$C:$C,Projections!$F33,Goalies!$A:$A,Projections!H$2) -> 1.02 | I33: =SUMIFS(Goalies!$J:$J,Goalies!$C:$C,Projections!$F33,Goalies!$A:$A,Projections!I$2) -> 1.02 | J33: =SUMIFS(Goalies!$J:$J,Goalies!$C:$C,Projections!$F33,Goalies!$A:$A,Projections!J$2) -> 0.99 | K33: =SUMIFS(Goalies!$J:$J,Goalies!$C:$C,Projections!$F33,Goalies!$A:$A,Projections!K$2) -> 0.99 | L33: =IFERROR($G33*H34,0) -> 3.1117181 | M33: =IFERROR($G33*I34,0) -> 6.7340772 | N33: =IFERROR($G33*J34,0) -> 3.1117181 | O33: =IFERROR($G33*K34,0) -> 6.7340772 | P33: =_xlfn.XLOOKUP(B33,'2026'!A:A,'2026'!AS:AS) -> Neutral | Q33: {=_xlfn.XLOOKUP(1, (Goalies!C:C=Projections!W33)*(Goalies!A:A=Projections!$Q$4), Goalies!D:D)} -> Jacob Markstrom | R33: {=_xlfn.XLOOKUP(1, (Goalies!C:C=Projections!W33)*(Goalies!A:A=Projections!$R$4), Goalies!D:D)} -> Jake Allen | S33: 0 | T33: =IFERROR(L33*S34+(1-S34)*M33,0) -> 3.1117181 | W33: =F33 -> NJD | X33: ='2026'!BJ31 -> -132 | Y33: ='2026'!BK31 -> -113 | Z33: ='2026'!BL31 -> 113 | AA33: ='2026'!BM31 -> 140
A34: =IF(D34=0,"0",(_xlfn.XLOOKUP(B34,'2026'!A:A,'2026'!C:C))) -> 46045 | B34: 2025020807 VAN | C34: 2025020807 | D34: =_xlfn.XLOOKUP(B34,'2026'!A:A,'2026'!AT:AT) -> 2.7718804 | E34: =_xlfn.XLOOKUP(B34,'2026'!A:A,'2026'!Z:Z) -> 1.03 | F34: =_xlfn.XLOOKUP(B34,'2026'!A:A,'2026'!E:E) -> VAN | G34: =D34/E33 -> 2.7175298 | H34: =SUMIFS(Goalies!$J:$J,Goalies!$C:$C,Projections!$F34,Goalies!$A:$A,Projections!H$4) -> 0.975 | I34: =SUMIFS(Goalies!$J:$J,Goalies!$C:$C,Projections!$F34,Goalies!$A:$A,Projections!I$4) -> 2.11 | J34: =SUMIFS(Goalies!$J:$J,Goalies!$C:$C,Projections!$F34,Goalies!$A:$A,Projections!J$4) -> 0.975 | K34: =SUMIFS(Goalies!$J:$J,Goalies!$C:$C,Projections!$F34,Goalies!$A:$A,Projections!K$4) -> 2.11 | L34: =IFERROR($G34*H33,0) -> 2.7718804 | M34: =IFERROR($G34*I33,0) -> 2.7718804 | N34: =IFERROR($G34*J33,0) -> 2.6903545 | O34: =IFERROR($G34*K33,0) -> 2.6903545 | P34: =_xlfn.XLOOKUP(B34,'2026'!A:A,'2026'!AS:AS) -> Neutral | Q34: {=_xlfn.XLOOKUP(1, (Goalies!C:C=Projections!W34)*(Goalies!A:A=Projections!$Q$4), Goalies!D:D)} -> Thatcher Demko | R34: {=_xlfn.XLOOKUP(1, (Goalies!C:C=Projections!W34)*(Goalies!A:A=Projections!$R$4), Goalies!D:D)} -> Kevin Lankinen | S34: 1 | T34: =IFERROR(L34*S33+(1-S33)*N34,0) -> 2.6903545 | W34: =F34 -> VAN | X34: ='2026'!BJ32 -> 132 | Y34: ='2026'!BK32 -> 113 | Z34: ='2026'!BL32 -> -113 | AA34: ='2026'!BM32 -> -140
A35: =IF(D35=0,"0",(_xlfn.XLOOKUP(B35,'2026'!A:A,'2026'!C:C))) -> 46045 | B35: 2025020808 NYR | C35: 2025020808 | D35: =_xlfn.XLOOKUP(B35,'2026'!A:A,'2026'!AT:AT) -> 2.9671483 | E35: =_xlfn.XLOOKUP(B35,'2026'!A:A,'2026'!Z:Z) -> 1.05 | F35: =_xlfn.XLOOKUP(B35,'2026'!A:A,'2026'!E:E) -> NYR | G35: =D35/E36 -> 3.0277024 | H35: =SUMIFS(Goalies!$J:$J,Goalies!$C:$C,Projections!$F35,Goalies!$A:$A,Projections!H$2) -> 0.97 | I35: =SUMIFS(Goalies!$J:$J,Goalies!$C:$C,Projections!$F35,Goalies!$A:$A,Projections!I$2) -> 0.97 | J35: =SUMIFS(Goalies!$J:$J,Goalies!$C:$C,Projections!$F35,Goalies!$A:$A,Projections!J$2) -> 1.05 | K35: =SUMIFS(Goalies!$J:$J,Goalies!$C:$C,Projections!$F35,Goalies!$A:$A,Projections!K$2) -> 1.05 | L35: =IFERROR($G35*H36,0) -> 3.1185334 | M35: =IFERROR($G35*I36,0) -> 2.9671483 | N35: =IFERROR($G35*J36,0) -> 3.1185334 | O35: =IFERROR($G35*K36,0) -> 2.9671483 | P35: =_xlfn.XLOOKUP(B35,'2026'!A:A,'2026'!AS:AS) -> Neutral | Q35: {=_xlfn.XLOOKUP(1, (Goalies!C:C=Projections!W35)*(Goalies!A:A=Projections!$Q$4), Goalies!D:D)} -> Igor Shesterkin | R35: {=_xlfn.XLOOKUP(1, (Goalies!C:C=Projections!W35)*(Goalies!A:A=Projections!$R$4), Goalies!D:D)} -> Jonathan Quick | S35: 1 | T35: =IFERROR(L35*S36+(1-S36)*M35,0) -> 3.1185334 | W35: =F35 -> NYR | X35: ='2026'!BJ33 -> -106 | Y35: ='2026'!BK33 -> -144 | Z35: ='2026'!BL33 -> -117 | AA35: ='2026'!BM33 -> 109
A36: =IF(D36=0,"0",(_xlfn.XLOOKUP(B36,'2026'!A:A,'2026'!C:C))) -> 46045 | B36: 2025020808 SJS | C36: 2025020808 | D36: =_xlfn.XLOOKUP(B36,'2026'!A:A,'2026'!AT:AT) -> 3.3155182 | E36: =_xlfn.XLOOKUP(B36,'2026'!A:A,'2026'!Z:Z) -> 0.98 | F36: =_xlfn.XLOOKUP(B36,'2026'!A:A,'2026'!E:E) -> SJS | G36: =D36/E35 -> 3.1576364 | H36: =SUMIFS(Goalies!$J:$J,Goalies!$C:$C,Projections!$F36,Goalies!$A:$A,Projections!H$4) -> 1.03 | I36: =SUMIFS(Goalies!$J:$J,Goalies!$C:$C,Projections!$F36,Goalies!$A:$A,Projections!I$4) -> 0.98 | J36: =SUMIFS(Goalies!$J:$J,Goalies!$C:$C,Projections!$F36,Goalies!$A:$A,Projections!J$4) -> 1.03 | K36: =SUMIFS(Goalies!$J:$J,Goalies!$C:$C,Projections!$F36,Goalies!$A:$A,Projections!K$4) -> 0.98 | L36: =IFERROR($G36*H35,0) -> 3.0629073 | M36: =IFERROR($G36*I35,0) -> 3.0629073 | N36: =IFERROR($G36*J35,0) -> 3.3155182 | O36: =IFERROR($G36*K35,0) -> 3.3155182 | P36: =_xlfn.XLOOKUP(B36,'2026'!A:A,'2026'!AS:AS) -> Neutral | Q36: {=_xlfn.XLOOKUP(1, (Goalies!C:C=Projections!W36)*(Goalies!A:A=Projections!$Q$4), Goalies!D:D)} -> Alex Nedeljkovic | R36: {=_xlfn.XLOOKUP(1, (Goalies!C:C=Projections!W36)*(Goalies!A:A=Projections!$R$4), Goalies!D:D)} -> Yaroslav Askarov | S36: 1 | T36: =IFERROR(L36*S35+(1-S35)*N36,0) -> 3.0629073 | W36: =F36 -> SJS | X36: ='2026'!BJ34 -> 106 | Y36: ='2026'!BK34 -> 144 | Z36: ='2026'!BL34 -> 117 | AA36: ='2026'!BM34 -> -109
A37: =IF(D37=0,"0",(_xlfn.XLOOKUP(B37,'2026'!A:A,'2026'!C:C))) -> 0 | D37: =_xlfn.XLOOKUP(B37,'2026'!A:A,'2026'!AT:AT) -> 0 | E37: =_xlfn.XLOOKUP(B37,'2026'!A:A,'2026'!Z:Z) -> 0 | F37: =_xlfn.XLOOKUP(B37,'2026'!A:A,'2026'!E:E) -> 0 | G37: =D37/E38 -> #DIV/0! | H37: =SUMIFS(Goalies!$J:$J,Goalies!$C:$C,Projections!$F37,Goalies!$A:$A,Projections!H$2) -> 0 | I37: =SUMIFS(Goalies!$J:$J,Goalies!$C:$C,Projections!$F37,Goalies!$A:$A,Projections!I$2) -> 0 | J37: =SUMIFS(Goalies!$J:$J,Goalies!$C:$C,Projections!$F37,Goalies!$A:$A,Projections!J$2) -> 0 | K37: =SUMIFS(Goalies!$J:$J,Goalies!$C:$C,Projections!$F37,Goalies!$A:$A,Projections!K$2) -> 0 | L37: =IFERROR($G37*H38,0) -> 0 | M37: =IFERROR($G37*I38,0) -> 0 | N37: =IFERROR($G37*J38,0) -> 0 | O37: =IFERROR($G37*K38,0) -> 0 | P37: =_xlfn.XLOOKUP(B37,'2026'!A:A,'2026'!AS:AS) -> 0 | Q37: {=_xlfn.XLOOKUP(1, (Goalies!C:C=Projections!W37)*(Goalies!A:A=Projections!$Q$4), Goalies!D:D)} -> #N/A | R37: {=_xlfn.XLOOKUP(1, (Goalies!C:C=Projections!W37)*(Goalies!A:A=Projections!$R$4), Goalies!D:D)} -> #N/A | S37: 1 | T37: =IFERROR(L37*S38+(1-S38)*M37,0) -> 0 | W37: =F37 -> 0 | X37: ='2026'!BJ35 -> #N/A | Y37: ='2026'!BK35 -> #N/A | Z37: ='2026'!BL35 -> #N/A | AA37: ='2026'!BM35 -> #N/A
A38: =IF(D38=0,"0",(_xlfn.XLOOKUP(B38,'2026'!A:A,'2026'!C:C))) -> 0 | D38: =_xlfn.XLOOKUP(B38,'2026'!A:A,'2026'!AT:AT) -> 0 | E38: =_xlfn.XLOOKUP(B38,'2026'!A:A,'2026'!Z:Z) -> 0 | F38: =_xlfn.XLOOKUP(B38,'2026'!A:A,'2026'!E:E) -> 0 | G38: =D38/E37 -> #DIV/0! | H38: =SUMIFS(Goalies!$J:$J,Goalies!$C:$C,Projections!$F38,Goalies!$A:$A,Projections!H$4) -> 0 | I38: =SUMIFS(Goalies!$J:$J,Goalies!$C:$C,Projections!$F38,Goalies!$A:$A,Projections!I$4) -> 0 | J38: =SUMIFS(Goalies!$J:$J,Goalies!$C:$C,Projections!$F38,Goalies!$A:$A,Projections!J$4) -> 0 | K38: =SUMIFS(Goalies!$J:$J,Goalies!$C:$C,Projections!$F38,Goalies!$A:$A,Projections!K$4) -> 0 | L38: =IFERROR($G38*H37,0) -> 0 | M38: =IFERROR($G38*I37,0) -> 0 | N38: =IFERROR($G38*J37,0) -> 0 | O38: =IFERROR($G38*K37,0) -> 0 | P38: =_xlfn.XLOOKUP(B38,'2026'!A:A,'2026'!AS:AS) -> 0 | Q38: {=_xlfn.XLOOKUP(1, (Goalies!C:C=Projections!W38)*(Goalies!A:A=Projections!$Q$4), Goalies!D:D)} -> #N/A | R38: {=_xlfn.XLOOKUP(1, (Goalies!C:C=Projections!W38)*(Goalies!A:A=Projections!$R$4), Goalies!D:D)} -> #N/A | S38: 1 | T38: =IFERROR(L38*S37+(1-S37)*N38,0) -> 0 | W38: =F38 -> 0 | X38: ='2026'!BJ36 -> #N/A | Y38: ='2026'!BK36 -> #N/A | Z38: ='2026'!BL36 -> #N/A | AA38: ='2026'!BM36 -> #N/A
A39: =IF(D39=0,"0",(_xlfn.XLOOKUP(B39,'2026'!A:A,'2026'!C:C))) -> 0 | D39: =_xlfn.XLOOKUP(B39,'2026'!A:A,'2026'!AT:AT) -> 0 | E39: =_xlfn.XLOOKUP(B39,'2026'!A:A,'2026'!Z:Z) -> 0 | F39: =_xlfn.XLOOKUP(B39,'2026'!A:A,'2026'!E:E) -> 0 | G39: =D39/E40 -> #DIV/0! | H39: =SUMIFS(Goalies!$J:$J,Goalies!$C:$C,Projections!$F39,Goalies!$A:$A,Projections!H$2) -> 0 | I39: =SUMIFS(Goalies!$J:$J,Goalies!$C:$C,Projections!$F39,Goalies!$A:$A,Projections!I$2) -> 0 | J39: =SUMIFS(Goalies!$J:$J,Goalies!$C:$C,Projections!$F39,Goalies!$A:$A,Projections!J$2) -> 0 | K39: =SUMIFS(Goalies!$J:$J,Goalies!$C:$C,Projections!$F39,Goalies!$A:$A,Projections!K$2) -> 0 | L39: =IFERROR($G39*H40,0) -> 0 | M39: =IFERROR($G39*I40,0) -> 0 | N39: =IFERROR($G39*J40,0) -> 0 | O39: =IFERROR($G39*K40,0) -> 0 | P39: =_xlfn.XLOOKUP(B39,'2026'!A:A,'2026'!AS:AS) -> 0 | Q39: {=_xlfn.XLOOKUP(1, (Goalies!C:C=Projections!W39)*(Goalies!A:A=Projections!$Q$4), Goalies!D:D)} -> #N/A | R39: {=_xlfn.XLOOKUP(1, (Goalies!C:C=Projections!W39)*(Goalies!A:A=Projections!$R$4), Goalies!D:D)} -> #N/A | S39: 0.7 | T39: =IFERROR(L39*S40+(1-S40)*M39,0) -> 0 | W39: =F39 -> 0 | X39: ='2026'!BJ37 -> #N/A | Y39: ='2026'!BK37 -> #N/A | Z39: ='2026'!BL37 -> #N/A | AA39: ='2026'!BM37 -> #N/A
A40: =IF(D40=0,"0",(_xlfn.XLOOKUP(B40,'2026'!A:A,'2026'!C:C))) -> 0 | D40: =_xlfn.XLOOKUP(B40,'2026'!A:A,'2026'!AT:AT) -> 0 | E40: =_xlfn.XLOOKUP(B40,'2026'!A:A,'2026'!Z:Z) -> 0 | F40: =_xlfn.XLOOKUP(B40,'2026'!A:A,'2026'!E:E) -> 0 | G40: =D40/E39 -> #DIV/0! | H40: =SUMIFS(Goalies!$J:$J,Goalies!$C:$C,Projections!$F40,Goalies!$A:$A,Projections!H$4) -> 0 | I40: =SUMIFS(Goalies!$J:$J,Goalies!$C:$C,Projections!$F40,Goalies!$A:$A,Projections!I$4) -> 0 | J40: =SUMIFS(Goalies!$J:$J,Goalies!$C:$C,Projections!$F40,Goalies!$A:$A,Projections!J$4) -> 0 | K40: =SUMIFS(Goalies!$J:$J,Goalies!$C:$C,Projections!$F40,Goalies!$A:$A,Projections!K$4) -> 0 | L40: =IFERROR($G40*H39,0) -> 0 | M40: =IFERROR($G40*I39,0) -> 0 | N40: =IFERROR($G40*J39,0) -> 0 | O40: =IFERROR($G40*K39,0) -> 0 | P40: =_xlfn.XLOOKUP(B40,'2026'!A:A,'2026'!AS:AS) -> 0 | Q40: {=_xlfn.XLOOKUP(1, (Goalies!C:C=Projections!W40)*(Goalies!A:A=Projections!$Q$4), Goalies!D:D)} -> #N/A | R40: {=_xlfn.XLOOKUP(1, (Goalies!C:C=Projections!W40)*(Goalies!A:A=Projections!$R$4), Goalies!D:D)} -> #N/A | S40: 1 | T40: =IFERROR(L40*S39+(1-S39)*N40,0) -> 0 | W40: =F40 -> 0 | X40: ='2026'!BJ38 -> #N/A | Y40: ='2026'!BK38 -> #N/A | Z40: ='2026'!BL38 -> #N/A | AA40: ='2026'!BM38 -> #N/A
A41: =IF(D41=0,"0",(_xlfn.XLOOKUP(B41,'2026'!A:A,'2026'!C:C))) -> 0 | D41: =_xlfn.XLOOKUP(B41,'2026'!A:A,'2026'!AT:AT) -> 0 | E41: =_xlfn.XLOOKUP(B41,'2026'!A:A,'2026'!Z:Z) -> 0 | F41: =_xlfn.XLOOKUP(B41,'2026'!A:A,'2026'!E:E) -> 0 | G41: =D41/E42 -> #DIV/0! | H41: =SUMIFS(Goalies!$J:$J,Goalies!$C:$C,Projections!$F41,Goalies!$A:$A,Projections!H$2) -> 0 | I41: =SUMIFS(Goalies!$J:$J,Goalies!$C:$C,Projections!$F41,Goalies!$A:$A,Projections!I$2) -> 0 | J41: =SUMIFS(Goalies!$J:$J,Goalies!$C:$C,Projections!$F41,Goalies!$A:$A,Projections!J$2) -> 0 | K41: =SUMIFS(Goalies!$J:$J,Goalies!$C:$C,Projections!$F41,Goalies!$A:$A,Projections!K$2) -> 0 | L41: =IFERROR($G41*H42,0) -> 0 | M41: =IFERROR($G41*I42,0) -> 0 | N41: =IFERROR($G41*J42,0) -> 0 | O41: =IFERROR($G41*K42,0) -> 0 | P41: =_xlfn.XLOOKUP(B41,'2026'!A:A,'2026'!AS:AS) -> 0 | Q41: {=_xlfn.XLOOKUP(1, (Goalies!C:C=Projections!W41)*(Goalies!A:A=Projections!$Q$4), Goalies!D:D)} -> #N/A | R41: {=_xlfn.XLOOKUP(1, (Goalies!C:C=Projections!W41)*(Goalies!A:A=Projections!$R$4), Goalies!D:D)} -> #N/A | S41: 1 | T41: =IFERROR(L41*S42+(1-S42)*M41,0) -> 0 | W41: =F41 -> 0 | X41: ='2026'!BJ39 -> #N/A | Y41: ='2026'!BK39 -> #N/A | Z41: ='2026'!BL39 -> #N/A | AA41: ='2026'!BM39 -> #N/A
...

Sheet 2026
AV1: =Projections!V1 -> 3.03 | BJ1: =IF(BN1=0.5,100,IF(BN1>0.5,-ROUND(100*BN1/(1-BN1),0),ROUND(100*(1-BN1)/BN1,0))) -> 117 | BK1: =IF(BO1=0.5,100,IF(BO1>0.5,-ROUND(100*BO1/(1-BO1),0),ROUND(100*(1-BO1)/BO1,0))) -> -155 | BL1: =IF(BP1=0.5,100,IF(BP1>0.5,-ROUND(100*BP1/(1-BP1),0),ROUND(100*(1-BP1)/BP1,0))) -> -126 | BM1: =IF(BQ1=0.5,100,IF(BQ1>0.5,-ROUND(100*BQ1/(1-BQ1),0),ROUND(100*(1-BQ1)/BQ1,0))) -> 102 | BN1: =_xlfn.LET( _xlpm.a, MIN(AV1,AV2), _xlpm.b, MAX(AV1,AV2), _xlpm.wA, (_xlpm.a - FLOOR(_xlpm.a,0.05)) / 0.05, _xlpm.wB, (_xlpm.b - FLOOR(_xlpm.b,0.05)) / 0.05, _xlpm.aLo, FLOOR(_xlpm.a,0.05), _xlpm.aHi, CEILING(_xlpm.a,0.05), _xlpm.bLo, FLOOR(_xlpm.b,0.05), _xlpm.bHi, CEILING(_xlpm.b,0.05), _xlpm.pLL, SUMIFS($BT:$BT,$BR:$BR,_xlpm.aLo,$BS:$BS,_xlpm.bLo), _xlpm.pUL, SUMIFS($BT:$BT,$BR:$BR,_xlpm.aHi,$BS:$BS,_xlpm.bLo), _xlpm.pLU, SUMIFS($BT:$BT,$BR:$BR,_xlpm.aLo,$BS:$BS,_xlpm.bHi), _xlpm.pUU, SUMIFS($BT:$BT,$BR:$BR,_xlpm.aHi,$BS:$BS,_xlpm.bHi), _xlpm.num, (1-_xlpm.wA)*(1-_xlpm.wB)*_xlpm.pLL + _xlpm.wA*(1-_xlpm.wB)*_xlpm.pUL + (1-_xlpm.wA)*_xlpm.wB*_xlpm.pLU + _xlpm.wA*_xlpm.wB*_xlpm.pUU, _xlpm.den, (1-_xlpm.wA)*(1-_xlpm.wB)*--(_xlpm.pLL<>0) + _xlpm.wA*(1-_xlpm.wB)*--(_xlpm.pUL<>0) + (1-_xlpm.wA)*_xlpm.wB*--(_xlpm.pLU<>0) + _xlpm.wA*_xlpm.wB*--(_xlpm.pUU<>0), _xlpm.interp, IF(_xlpm.den=0, NA(), _xlpm.num/_xlpm.den), IF(AV1>AV2, 1-_xlpm.interp, _xlpm.interp) ) -> 0.4606308 | BO1: =1-BO2 -> 0.6077808 | BP1: =1-BP2 -> 0.5583831 | BQ1: =1-BQ2 -> 0.4959244
AV2: =Projections!V2 -> 3.26 | BJ2: =IF(BN2=0.5,100,IF(BN2>0.5,-ROUND(100*BN2/(1-BN2),0),ROUND(100*(1-BN2)/BN2,0))) -> -117 | BK2: =IF(BO2=0.5,100,IF(BO2>0.5,-ROUND(100*BO2/(1-BO2),0),ROUND(100*(1-BO2)/BO2,0))) -> 155 | BL2: =IF(BP2=0.5,100,IF(BP2>0.5,-ROUND(100*BP2/(1-BP2),0),ROUND(100*(1-BP2)/BP2,0))) -> 126 | BM2: =IF(BQ2=0.5,100,IF(BQ2>0.5,-ROUND(100*BQ2/(1-BQ2),0),ROUND(100*(1-BQ2)/BQ2,0))) -> -102 | BN2: =1-BN1 -> 0.5393692 | BO2: =_xlfn.LET( _xlpm.a, MIN(AV1,AV2), _xlpm.b, MAX(AV1,AV2), _xlpm.wA, (_xlpm.a - FLOOR(_xlpm.a,0.05)) / 0.05, _xlpm.wB, (_xlpm.b - FLOOR(_xlpm.b,0.05)) / 0.05, _xlpm.aLo, FLOOR(_xlpm.a,0.05), _xlpm.aHi, CEILING(_xlpm.a,0.05), _xlpm.bLo, FLOOR(_xlpm.b,0.05), _xlpm.bHi, CEILING(_xlpm.b,0.05), _xlpm.pLL, SUMIFS($BU:$BU,$BR:$BR,_xlpm.aLo,$BS:$BS,_xlpm.bLo), _xlpm.pUL, SUMIFS($BU:$BU,$BR:$BR,_xlpm.aHi,$BS:$BS,_xlpm.bLo), _xlpm.pLU, SUMIFS($BU:$BU,$BR:$BR,_xlpm.aLo,$BS:$BS,_xlpm.bHi), _xlpm.pUU, SUMIFS($BU:$BU,$BR:$BR,_xlpm.aHi,$BS:$BS,_xlpm.bHi), _xlpm.num, (1-_xlpm.wA)*(1-_xlpm.wB)*_xlpm.pLL + _xlpm.wA*(1-_xlpm.wB)*_xlpm.pUL + (1-_xlpm.wA)*_xlpm.wB*_xlpm.pLU + _xlpm.wA*_xlpm.wB*_xlpm.pUU, _xlpm.den, (1-_xlpm.wA)*(1-_xlpm.wB)*--(_xlpm.pLL<>0) + _xlpm.wA*(1-_xlpm.wB)*--(_xlpm.pUL<>0) + (1-_xlpm.wA)*_xlpm.wB*--(_xlpm.pLU<>0) + _xlpm.wA*_xlpm.wB*--(_xlpm.pUU<>0), _xlpm.interp, IF(_xlpm.den=0, NA(), _xlpm.num/_xlpm.den), _xlpm.interp ) -> 0.3922192 | BP2: =_xlfn.LET( _xlpm.a, MIN(AV1,AV2), _xlpm.b, MAX(AV1,AV2), _xlpm.wA, (_xlpm.a - FLOOR(_xlpm.a,0.05)) / 0.05, _xlpm.wB, (_xlpm.b - FLOOR(_xlpm.b,0.05)) / 0.05, _xlpm.aLo, FLOOR(_xlpm.a,0.05), _xlpm.aHi, CEILING(_xlpm.a,0.05), _xlpm.bLo, FLOOR(_xlpm.b,0.05), _xlpm.bHi, CEILING(_xlpm.b,0.05), _xlpm.pLL, SUMIFS($BV:$BV,$BR:$BR,_xlpm.aLo,$BS:$BS,_xlpm.bLo), _xlpm.pUL, SUMIFS($BV:$BV,$BR:$BR,_xlpm.aHi,$BS:$BS,_xlpm.bLo), _xlpm.pLU, SUMIFS($BV:$BV,$BR:$BR,_xlpm.aLo,$BS:$BS,_xlpm.bHi), _xlpm.pUU, SUMIFS($BV:$BV,$BR:$BR,_xlpm.aHi,$BS:$BS,_xlpm.bHi), _xlpm.num, (1-_xlpm.wA)*(1-_xlpm.wB)*_xlpm.pLL + _xlpm.wA*(1-_xlpm.wB)*_xlpm.pUL + (1-_xlpm.wA)*_xlpm.wB*_xlpm.pLU + _xlpm.wA*_xlpm.wB*_xlpm.pUU, _xlpm.den, (1-_xlpm.wA)*(1-_xlpm.wB)*--(_xlpm.pLL<>0) + _xlpm.wA*(1-_xlpm.wB)*--(_xlpm.pUL<>0) + (1-_xlpm.wA)*_xlpm.wB*--(_xlpm.pLU<>0) + _xlpm.wA*_xlpm.wB*--(_xlpm.pUU<>0), _xlpm.interp, IF(_xlpm.den=0, NA(), _xlpm.num/_xlpm.den), _xlpm.interp ) -> 0.4416169 | BQ2: =_xlfn.LET( _xlpm.a, MIN(AV1,AV2), _xlpm.b, MAX(AV1,AV2), _xlpm.wA, (_xlpm.a - FLOOR(_xlpm.a,0.05)) / 0.05, _xlpm.wB, (_xlpm.b - FLOOR(_xlpm.b,0.05)) / 0.05, _xlpm.aLo, FLOOR(_xlpm.a,0.05), _xlpm.aHi, CEILING(_xlpm.a,0.05), _xlpm.bLo, FLOOR(_xlpm.b,0.05), _xlpm.bHi, CEILING(_xlpm.b,0.05), _xlpm.pLL, SUMIFS($BW:$BW,$BR:$BR,_xlpm.aLo,$BS:$BS,_xlpm.bLo), _xlpm.pUL, SUMIFS($BW:$BW,$BR:$BR,_xlpm.aHi,$BS:$BS,_xlpm.bLo), _xlpm.pLU, SUMIFS($BW:$BW,$BR:$BR,_xlpm.aLo,$BS:$BS,_xlpm.bHi), _xlpm.pUU, SUMIFS($BW:$BW,$BR:$BR,_xlpm.aHi,$BS:$BS,_xlpm.bHi), _xlpm.num, (1-_xlpm.wA)*(1-_xlpm.wB)*_xlpm.pLL + _xlpm.wA*(1-_xlpm.wB)*_xlpm.pUL + (1-_xlpm.wA)*_xlpm.wB*_xlpm.pLU + _xlpm.wA*_xlpm.wB*_xlpm.pUU, _xlpm.den, (1-_xlpm.wA)*(1-_xlpm.wB)*--(_xlpm.pLL<>0) + _xlpm.wA*(1-_xlpm.wB)*--(_xlpm.pUL<>0) + (1-_xlpm.wA)*_xlpm.wB*--(_xlpm.pLU<>0) + _xlpm.wA*_xlpm.wB*--(_xlpm.pUU<>0), _xlpm.interp, IF(_xlpm.den=0, NA(), _xlpm.num/_xlpm.den), _xlpm.interp ) -> 0.5040756
AV3: =Projections!T5 -> 5.9102465 | BJ3: =IF(BN3=0.5,100,IF(BN3>0.5,-ROUND(100*BN3/(1-BN3),0),ROUND(100*(1-BN3)/BN3,0))) -> #N/A | BK3: =IF(BO3=0.5,100,IF(BO3>0.5,-ROUND(100*BO3/(1-BO3),0),ROUND(100*(1-BO3)/BO3,0))) -> #N/A | BL3: =IF(BP3=0.5,100,IF(BP3>0.5,-ROUND(100*BP3/(1-BP3),0),ROUND(100*(1-BP3)/BP3,0))) -> #N/A | BM3: =IF(BQ3=0.5,100,IF(BQ3>0.5,-ROUND(100*BQ3/(1-BQ3),0),ROUND(100*(1-BQ3)/BQ3,0))) -> #N/A | BN3: =_xlfn.LET( _xlpm.a, MIN(AV3,AV4), _xlpm.b, MAX(AV3,AV4), _xlpm.wA, (_xlpm.a - FLOOR(_xlpm.a,0.05)) / 0.05, _xlpm.wB, (_xlpm.b - FLOOR(_xlpm.b,0.05)) / 0.05, _xlpm.aLo, FLOOR(_xlpm.a,0.05), _xlpm.aHi, CEILING(_xlpm.a,0.05), _xlpm.bLo, FLOOR(_xlpm.b,0.05), _xlpm.bHi, CEILING(_xlpm.b,0.05), _xlpm.pLL, SUMIFS($BT:$BT,$BR:$BR,_xlpm.aLo,$BS:$BS,_xlpm.bLo), _xlpm.pUL, SUMIFS($BT:$BT,$BR:$BR,_xlpm.aHi,$BS:$BS,_xlpm.bLo), _xlpm.pLU, SUMIFS($BT:$BT,$BR:$BR,_xlpm.aLo,$BS:$BS,_xlpm.bHi), _xlpm.pUU, SUMIFS($BT:$BT,$BR:$BR,_xlpm.aHi,$BS:$BS,_xlpm.bHi), _xlpm.num, (1-_xlpm.wA)*(1-_xlpm.wB)*_xlpm.pLL + _xlpm.wA*(1-_xlpm.wB)*_xlpm.pUL + (1-_xlpm.wA)*_xlpm.wB*_xlpm.pLU + _xlpm.wA*_xlpm.wB*_xlpm.pUU, _xlpm.den, (1-_xlpm.wA)*(1-_xlpm.wB)*--(_xlpm.pLL<>0) + _xlpm.wA*(1-_xlpm.wB)*--(_xlpm.pUL<>0) + (1-_xlpm.wA)*_xlpm.wB*--(_xlpm.pLU<>0) + _xlpm.wA*_xlpm.wB*--(_xlpm.pUU<>0), _xlpm.interp, IF(_xlpm.den=0, NA(), _xlpm.num/_xlpm.den), IF(AV3>AV4, 1-_xlpm.interp, _xlpm.interp) ) -> #N/A | BO3: =1-BO4 -> #N/A | BP3: =1-BP4 -> #N/A | BQ3: =1-BQ4 -> #N/A
